Workbook
Name Excel_BuiltIn__FilterDatabase_4: #REF!

Sheet ГОЛОВНА
C6: MHI RAC
J7: GALACTIC побутові | N7: REMAK
C8: МУЛЬТИСПЛІТ СИСТЕМИ | Q8: 46143
Q9: КУРС МІЦ
C10: PAC | N10: REMAK ЗАВІСИ
Q11: 44 | R11: $
C12: VRF Зовнішні блоки | J12: Galactic Напівпром
C14: VRF Внутрішні R410A
C16: VRF Внутрішні KXZE1-W R32 | E16: VRF Внутрішні New KXZ3 R32
J17: Galactic ККБ | N17: FRICO
C18: ККБ MHI
C20: Аксесуари до KX систем
C22: Теплові насоси | J22: Galactic VRF
N23: SYSTEMAIR
C24: HeatGuard
C26: WineGuard | M26: РОЗПРОДАЖ! SYSTEMAIR
J27: Теплові насоси
C28: CLINT
C32: Інструмент для монтажу та сервісу | H32: АКЦІЯ! ЗНИЖКИ! РОЗПРОДАЖ!
N33: MASTAS
C35: АКЦІЯ! ERRECOM
J36: Витратні матеріали
B40: Ціни вказані в У.Є. Оплата здійснюється за безготівковим розрахунком, за комерційним курсом.
B42: http://sun-ice.com.ua/ | G42: http://www.clint.com.ua/ | L42: https://www.systemair.com/ua/
G44: http://www.galactic.ua/ | L44: http://www.remak.eu/ua
B46: http://www.mitsubishi-srk.com.ua/ | G46: http://www.r134.com.ua/ | L46: http://www.frico.se/ru
B48: Документація
B49: САН-АЙС ЗАГАЛЬНИЙ ДОСТУП (технічні мануали, фото, каталоги):
B51: Технічна документація Mitsubishi H.I. | C51: https://drive.google.com/drive/folders/1vAOd25oKeZ-vYKXKH_M8F7iGVdem_FOt?usp=sharing
B52: Фото обладнання Mitsubishi H.I. | C52: https://drive.google.com/drive/folders/0B0-wc8ovylnTZDljLTZ1V2htdVU?resourcekey=0-fQImegIV6_Bp9WQz1vCuGQ
B54: Технічна документація Galactic | C54: https://drive.google.com/drive/folders/1PTHnguhY7dvsvpBM5-b9XbUu7MIsYW7G?usp=sharing
B55: Фото обладнання Galactic | C55: https://drive.google.com/drive/folders/1DTtGjKY8uZUVTJ_Pbs5VEzVAkL83F-lm

Sheet АКЦІЯ
C2: АКЦІЯ!
B5: Обладнання зі знижкою 40%
B6: Припливна установка CIAT | D6: Знижка, %
B7: AHU CLIMACIAT airtech 50 | C7: Припливно-витяжна установка AHU CLIMACIAT airtech 50 з пластинчастим рекуператором | D7: Обговорюється
C8: Внутрішні блоки VRF Mitsubishi Heavy
B9: FDTS71KXE6F | C9: розпродаж залишків на складі - 1шт | D9: 10% додатково до базової
B10: FDTW45KXE6D | C10: розпродаж залишків на складі - 2шт | D10: 10% додатково до базової
B11: FDK45KXE6 | C11: розпродаж залишків на складі - 2шт | D11: 10% додатково до базової
B12: FDQS22KXE6 | C12: розпродаж залишків на складі - 1шт | D12: 10% додатково до базової
B13: FDKA56KXE4R | C13: розпродаж залишків на складі - 2шт | D13: 10% додатково до базової
B14: FDTS71KXE6D | C14: розпродаж залишків на складі - 1шт | D14: 10% додатково до базової
B15: FDTA45KXE4R | C15: розпродаж залишків на складі - 1шт | D15: 10% додатково до базової
B16: FDEA112KXE4R | C16: розпродаж залишків на складі - 1шт | D16: 10% додатково до базової
B18: Розпродаж
C19: Чіллер серії Compact Line CHA/CLK 15 (4,5 кВт) | D19: 2700 $
C20: MHA/K 25 (ККБ 8,0 кВт) | D20: 1892 $
C21: MHA/K 31 (ККБ 9,2 кВт) | D21: 1956 $
C22: MHA/K 41 (ККБ 10,8 кВт) | D22: 2113 $
C23: MHA/K 51 (ККБ 13,2 кВт) | D23: 2830 $
C24: MHA/K 71 (ККБ 19,1 кВт) | D24: 3123 $
B26: Обладнання зі знижкою
C27: V-MULTI | D27: Ціна для дилера
C28: FDT50VF/T-PSA-3BW-E * 2 + FDC100VN(VS)+пульт | D28: 3500
C29: FDT50VF/T-PSA-3BW-E * 3 + FDC140VN(VS)+пульт | D29: 4800
C30: FDT50VF/T-PSA-3BW-E * 4 + FDC200VS+пульт | D30: 6500
B34: Lovair CLIMA | C34: Професійний генератор озону. Вбиває бактерії, плісняву, розкладає погані запахи, перетворює токсичні гази на нешкідливі. | D34: 0.4
B35: Детальніше: | C35: https://r134.com.ua/index.php?route=product/product&product_id=32&search=Lovair+CLIMA
B37: http://r134.com.ua/index.php?searchword=rw-mini&ordering=&searchphrase=all&Itemid=398&option=com_search

Sheet ПОБУТОВІ
J4: =ГОЛОВНА!Q11 -> 44
B6: МОДЕЛЬ | C6: ТИП БЛОКУ | D6: НАЙМЕНУВАННЯ БЛОКУ | E6: ПРОДУКТИВНІСТЬ | F6: Споживана потужність | G6: Коефіцієнт ефективності | H6: МІЦ, грн. | I6: Ціна дилер у.е., у.е.=$ | J6: Ціна дилер по блоково у.е., у.е.=$
E7: Охолодження, кВт | F7: Охолодження, кВт | G7: EER (холод)
E8: Нагрів, кВт | F8: Нагрів, кВт | G8: COP (тепло)
B9: RAC - СЕРІЯ ПОБУТОВІ КОНДИЦІОНЕРИ
B10: Спліт-системи настінного типу (холод-тепло) холодоагент R410
B11: БІЗНЕС-КЛАС ON/OFF R410 Натуральний ензимний антибактеріальний фільтр, фотокаталітичний фільтр з ефектом, що дезодорує, антибактеріальний вентилятор, здатність генерувати негативно заряджені іони, мінімальний рівень шуму, мінімальні показники енергоспоживання, новий дизайн внутрішнього блоку. Підведення живлення здійснюється до внутрішнього блоку. Країна-виробник - THAILAND
B12: SRK50HE-S1 | C12: внутр. | D12: SRK50HE-S1 | E12: 4.7 | F12: 1.41 | G12: 3.33 | H12: =I12/0.8*$J$4 -> 33550 | I12: 610 | J12: 244 | K12: !Без додаткових знижок!
C13: зовніш. | D13: SRС50HE-S1 | E13: 5.3 | F13: 1.4 | G13: 3.79 | J13: 366
B14: !!!Популярний інвертор R410 Антибактеріальне покриття вентилятора, мінімальний рівень шуму, функція самоочищення. Підведення живлення здійснюється до зовнішнього блоку. Країна-виробник - THAILAND. На моделях SRK45ZSPR-S, SRK63ZSPR-S, SRK71ZSPR-S, SRK80ZSPR-S встановлений двороторний компресор, фільтр тонкого очищення повітря, ІЧ пульт з тижневим таймером. Моделі SRK63ZSPR-S, SRK71ZSPR-S, SRK80ZSPR-S Wi-Fi ready. Wi-Fi адаптер INAWMMHI001/000.
B15: SRK20ZSPR-S | C15: внутр. | D15: SRK20ZSPR-S | E15: 2.0 (0.9~2.8) | F15: 0.545 (0.25~1.01) | G15: 3.67 | H15: 27000 | I15: 525 | J15: 195
C16: зовніш. | D16: SRC20ZSPR-S | E16: 2.7 (0.8~3.9) | F16: 0.71 (0.20~1.43) | G16: 3.80 | J16: 330
B17: SRK25ZSPR-S | C17: внутр. | D17: SRK25ZSPR-S | E17: 2.5 (0.9~2.8) | F17: 0.78 (0.25~1.01) | G17: 3.21 | H17: 29000 | I17: 560 | J17: 211
C18: зовніш. | D18: SRC25ZSPR-S | E18: 2.8 (0.8~3.9) | F18: 0.755 (0.20~1.43) | G18: 3.71 | J18: 349
B19: SRK35ZSPR-S | C19: внутр. | D19: SRK35ZSPR-S | E19: 3.2 (0.9~3.5) | F19: 0.995 (0.23~1.32) | G19: 3.22 | H19: 33000 | I19: 650 | J19: 252
C20: зовніш. | D20: SRC35ZSPR-S | E20: 3.6 (0.9~4.3) | F20: 0.995 (0.19~1.31) | G20: 3.62 | J20: 398
B21: SRK45ZSPR-S | C21: внутр. | D21: SRK45ZSPR-S | E21: 4.5 (0.9~4.8) | F21: 1.495 (0.22~1.98) | G21: 3.01 | H21: 56000 | I21: 1100 | J21: 417
C22: зовніш. | D22: SRC45ZSPR-S | E22: 5.0 (0.8~5.8) | F22: 1.385 (0.2~1.86) | G22: 3.61 | J22: 683
B23: SRK63ZSPR-S | C23: внутр. | D23: SRK63ZSPR-S | E23: 6.3 (1.2~7.1) | F23: 1.85 (0.2~2.5) | G23: 3.41 | H23: 77000 | I23: 1510 | J23: 603
C24: зовніш. | D24: SRC63ZSPR-S | E24: 7.1 (0.8~9.0) | F24: 1.74 (0.2~2.8) | G24: 4.08 | J24: 907
B25: SRK71ZSPR-S | C25: внутр. | D25: SRK71ZSPR-S | E25: 7.1 (2.3~7.7) | F25: 2.05 (0.5~2.7) | G25: 3.46 | H25: 89000 | I25: 1745 | J25: 696
C26: зовніш. | D26: SRC71ZSPR-S | E26: 8.0 (2.0~10.0) | F26: 2.06 (0.4~3.4) | G26: 3.88 | J26: 1049
B27: SRK80ZSPR-S | C27: внутр. | D27: SRK80ZSPR-S | E27: 8.0 (2.3~9.0) | F27: 2.35 (0.5~3.2) | G27: 3.40 | H27: 101000 | I27: 1990 | J27: 752
C28: зовніш. | D28: SRC80ZSPR-S | E28: 9.0 (2.1~10.5) | F28: 2.4 (0.4~3.5) | G28: 3.75 | J28: 1238
B29: Спліт-системи настінного типу (холод-тепло) холодоагент R32
B30: Популярний інвертор R32 Антибактеріальне покриття вентилятора, мінімальний рівень шуму, функція самоочищення. Підведення живлення здійснюється до зовнішнього блоку. Країна-виробник - THAILAND. Фільтр тонкого очищення повітря, ІЧ пульт з тижневим таймером.
B31: SRK25ZSP-W1 | C31: внутр. | D31: SRK25ZSP-W1 | E31: 2.5 (0.9~3.1) | F31: 0.71 | G31: 3.52 | H31: =I31/0.8*$J$4 -> 36575 | I31: 665 | J31: 244
C32: зовніш. | D32: SRC25ZSP-W1 | E32: 2.8 (1.0~4.1) | F32: 0.69 | G32: 4.05 | J32: 421
B33: SRK35ZSP-W1 | C33: внутр. | D33: SRK35ZSP-W1 | E33: 3.2 (0.9~3.7) | F33: 0.91 | G33: 3.52 | H33: =I33/0.8*$J$4 -> 40700 | I33: 740 | J33: 274
C34: зовніш. | D34: SRC35ZSP-W1 | E34: 3.6 (1.0~4.6) | F34: 0.93 | G34: 3.87 | J34: 466
B35: SRK45ZSP-W1 | C35: внутр. | D35: SRK45ZSP-W1 | E35: 4.5 (1.3~4.8) | F35: 1.35 | G35: 3.33 | H35: =I35/0.8*$J$4 -> 60500 | I35: 1100 | J35: 370
C36: зовніш. | D36: SRC45ZSP-W1 | E36: 5.0 (1.2~5.8) | F36: 1.36 | G36: 3.68 | J36: 730
B37: SRK50ZSP-W1 | C37: внутр. | D37: SRK50ZSP-W1 | E37: 5.0 (1.3~5.2) | F37: 1.74 | G37: 2.87 | H37: =I37/0.8*$J$4 -> 63800 | I37: 1160 | J37: 390
C38: зовніш. | D38: SRC50ZSP-W1 | E38: 5.6 (1.2~5.8) | F38: 1.66 | G38: 3.37 | J38: 770
B39: Серія ZTL-W R32 Новий інвертор має оновлений дизайн, оснащений антиалергенним фільтром, оновлений дизайн інфрачервоного пульта ДУ з підсвічуванням дисплею, антибактеріальне покриття вентилятора, мінімальний рівень шуму, функція самоочищення, живлення здійснюється до зовнішнього блоку. Wi-Fi з новим інтерфейсом вбудовано у стандартну комплектацію. Країна-виробник - THAILAND.
B40: SRK15ZTL-W | C40: внутр. | D40: SRK15ZTL-W | E40: 1.5 (0.7 ~ 2.5) | F40: 0.35 (0.20 ~ 0.85) | G40: 6.4 | H40: =I40/0.8*$J$4 -> 40700 | I40: 740 | J40: 361
C41: зовніш. | D41: SRC15ZTL-W | E41: 2.0 (0.9 ~ 4.1) | F41: 0.42 (0.21 ~ 1.39) | G41: 4.4 | J41: 379
B42: SRK20ZTL-W | C42: внутр. | D42: SRK20ZTL-W | E42: 2.0 (0.7 ~ 2.8) | F42: 0.51 (0.20 ~ 0.92) | G42: 6.7 | H42: =I42/0.8*$J$4 -> 41800 | I42: 760 | J42: 372
C43: зовніш. | D43: SRC20ZTL-W | E43: 2.7 (0.9 ~ 4.2) | F43: 0.64 (0.21 ~ 1.40) | G43: 4.4 | J43: 388
B44: SRK25ZTL-W | C44: внутр. | D44: SRK25ZTL-W | E44: 2.5 (0.8 ~ 3.2) | F44: 0.58 (0.19 ~ 0.95) | G44: 6.9 | H44: =I44/0.8*$J$4 -> 45100 | I44: 820 | J44: 406
...

Sheet МУЛЬТИСИСТЕМИ
I4: =ГОЛОВНА!Q11 -> 44
B5: МОДЕЛЬ | C5: ТИП БЛОКУ | D5: НАЙМЕНУВАННЯ БЛОКУ | E5: ПРОДУКТИВНІСТЬ | F5: Коефіцієнт ефективності | G5: МІЦ, грн | H5: Ціна дилер у.е., у.е.=$
E6: Охолодження, кВт | F6: EER (холод)
E7: Нагрів, кВт | F7: COP (тепло)
B8: Мультиспліт системи INVERTER ( холод-тепло ) R32
B10: SCM40ZS-W | C10: зовніш. | D10: Підключення до 2 внутрішніх блоків | E10: 4,0 (1,5 - 5,9) | F10: 4.76 | G10: =SUM(H10)/0.8*$I$4 -> 59950 | H10: 1090
E11: 4,5 (1,0 - 6,3) | F11: 5
B12: SCM45ZS-W | C12: зовніш. | D12: Підключення до 2 внутрішніх блоків | E12: 4,5 (1,5 - 6,4) | F12: 5.01 | G12: =SUM(H12)/0.8*$I$4 -> 64900 | H12: 1180
E13: 5,3 (1,0 - 6,5) | F13: 5.35
B14: SCM50ZS-W | C14: зовніш. | D14: Підключення до 3 внутрішніх блоків | E14: 5,0 (1,7 - 7,1) | F14: 4.76 | G14: =SUM(H14)/0.8*$I$4 -> 75020 | H14: 1364
E15: 6,0 (1,0 - 7,5) | F15: 4.84
B16: SCM60ZS-W | C16: зовніш. | D16: Підключення до 3 внутрішніх блоків | E16: 6,0 (1,7 - 7,5) | F16: 4.2 | G16: =SUM(H16)/0.8*$I$4 -> 92345 | H16: 1679
E17: 6,8 (1,0 - 7,5) | F17: 4.5
B18: SCM71ZS-W | C18: зовніш. | D18: Підключення до 4 внутрішніх блоків | E18: 7,1 (1,8 - 8,8) | F18: 4 | G18: =SUM(H18)/0.8*$I$4 -> 111650 | H18: 2030
E19: 8,6 (1,1 - 9,4) | F19: 4.3
B20: SCM80ZS-W | C20: зовніш. | D20: Підключення до 4 внутрішніх блоків | E20: 8,0 (1,8 - 9,2) | F20: 3.7 | G20: =SUM(H20)/0.8*$I$4 -> 124465 | H20: 2263
E21: 9,3 (1,1 - 9,8) | F21: 4.12
B22: SCM100ZS-W | C22: зовніш. | D22: Підключення до 5 внутрішніх блоків | E22: 10,0 (1,8 - 12,0) | F22: 3.5 | G22: =SUM(H22)/0.8*$I$4 -> 179355 | H22: 3261
E23: 12,0 (1,5 - 13,5) | F23: 4.1
B24: SCM125ZM-S | C24: зовніш. | D24: Підключення до 6 внутрішніх блоків | E24: 12,5 (1,8 - 14,0) | F24: 3.21 | G24: =SUM(H24)/0.8*$I$4 -> 190300 | H24: 3460
E25: 13,5 (1,5 - 14,0) | F25: 4.15
E26: Охолодження, кВт | F26: Нагрів, кВт
B27: SKM20ZSP-W | C27: внутр. | D27: Настінний | E27: 2 | F27: 3 | G27: =SUM(H27)/0.8*$I$4 -> 12650 | H27: 230
B28: SKM25ZSP-W | C28: внутр. | D28: Настінний | E28: 2.5 | F28: 3.4 | G28: =SUM(H28)/0.8*$I$4 -> 14520 | H28: 264
B29: SKM35ZSP-W | C29: внутр. | D29: Настінний | E29: 3.5 | F29: 4.5 | G29: =SUM(H29)/0.8*$I$4 -> 16060 | H29: 292
B30: SRK20ZS-W | C30: внутр. | D30: Настінний | E30: 2 | F30: 3 | G30: =SUM(H30)/0.8*$I$4 -> 18590 | H30: =ПОБУТОВІ!J55 -> 338
B31: SRK25ZS-W | C31: внутр. | D31: Настінний | E31: 2.5 | F31: 3.4 | G31: =SUM(H31)/0.8*$I$4 -> 20350 | H31: =ПОБУТОВІ!J57 -> 370
B32: SRK35ZS-W | C32: внутр. | D32: Настінний | E32: 3.5 | F32: 4.5 | G32: =SUM(H32)/0.8*$I$4 -> 23320 | H32: =ПОБУТОВІ!J59 -> 424
B33: SRK50ZS-W | C33: внутр. | D33: Настінний | E33: 5 | F33: 5.8 | G33: =SUM(H33)/0.8*$I$4 -> 32725 | H33: =ПОБУТОВІ!J61 -> 595
B34: SRK20ZS-WT | C34: внутр. | D34: Настінний | E34: 2 | F34: 3 | G34: =SUM(H34)/0.8*$I$4 -> 23265 | H34: =ПОБУТОВІ!J63 -> 423
B35: SRK20ZS-WB | C35: внутр. | D35: Настінний | E35: 2 | F35: 3 | G35: =SUM(H35)/0.8*$I$4 -> 23265 | H35: =ПОБУТОВІ!J65 -> 423
B36: SRK25ZS-WT | C36: внутр. | D36: Настінний | E36: 2.5 | F36: 3.4 | G36: =SUM(H36)/0.8*$I$4 -> 24585 | H36: =ПОБУТОВІ!J67 -> 447
B37: SRK25ZS-WB | C37: внутр. | D37: Настінний | E37: 2.5 | F37: 3.4 | G37: =SUM(H37)/0.8*$I$4 -> 24585 | H37: =ПОБУТОВІ!J69 -> 447
B38: SRK35ZS-WT | C38: внутр. | D38: Настінний | E38: 3.5 | F38: 4.5 | G38: =SUM(H38)/0.8*$I$4 -> 27720 | H38: =ПОБУТОВІ!J71 -> 504
B39: SRK35ZS-WB | C39: внутр. | D39: Настінний | E39: 3.5 | F39: 4.5 | G39: =SUM(H39)/0.8*$I$4 -> 27720 | H39: =ПОБУТОВІ!J73 -> 504
B40: SRK50ZS-WT | C40: внутр. | D40: Настінний | E40: 5 | F40: 5.8 | G40: =SUM(H40)/0.8*$I$4 -> 37015 | H40: =ПОБУТОВІ!J75 -> 673
B41: SRK50ZS-WB | C41: внутр. | D41: Настінний | E41: 5 | F41: 5.8 | G41: =SUM(H41)/0.8*$I$4 -> 37015 | H41: =ПОБУТОВІ!J77 -> 673
B42: SRK20ZSX-W | C42: внутр. | D42: Настінний | E42: 2 | F42: 3 | G42: =SUM(H42)/0.8*$I$4 -> 30690 | H42: =ПОБУТОВІ!J110 -> 558
B43: SRK25ZSX-W | C43: внутр. | D43: Настінний | E43: 2.5 | F43: 3.4 | G43: =SUM(H43)/0.8*$I$4 -> 33495 | H43: =ПОБУТОВІ!J112 -> 609
B44: SRK35ZSX-W | C44: внутр. | D44: Настінний | E44: 3.5 | F44: 4.5 | G44: =SUM(H44)/0.8*$I$4 -> 38390 | H44: =ПОБУТОВІ!J114 -> 698
...

Sheet НАПІВПРОМ
P1: Швидкий перехід
P2: Настінні SRK
P3: Стельові FDE
P4: Касетні FDT
P5: Касетні компактні FDTC
P6: Канальні середнього тиску FDUM
P7: Канальні високого тиску FDU
P8: Колонні FDF
B9: Модель | C9: INV | D9: Фазність | F9: Потужність, кВт | G9: Внутрішній | H9: Зовнішній | I9: Панель (касетного типу) | J9: Пульт | K9: Роздрібна ціна, у.е., у.е.=$
D10: 1ph | E10: 3ph | K10: Внутр. | L10: Зовніш. | M10: Панель | N10: Пульт | O10: Комплект
B11: Настінні
B12: Настінні SRK | C12: Hyper Inverter
C13: O | D13: O | F13: 7.1 | G13: SRK71ZR-W | H13: FDC71VNX-W | J13: бездротовий у комплекті | K13: 992 | L13: 2148 | O13: =SUM(K13:N13) -> 3140
C14: O | D14: O | F14: 10 | G14: SRK100ZR-W | H14: FDC100VNX-W | J14: бездротовий у комплекті | K14: 1105 | L14: 3271 | O14: =SUM(K14:N14) -> 4376
C15: O | E15: O | F15: 10 | G15: SRK100ZR-W | H15: FDC100VSX-W | J15: бездротовий у комплекті | K15: =K14 -> 1105 | L15: 3680 | O15: =SUM(K15:N15) -> 4785
C16: Micro Inverter
C17: O | D17: O | F17: 10 | G17: SRK100ZR-W | H17: FDC100VNA-W | J17: бездротовий у комплекті | K17: =K14 -> 1105 | L17: 2607 | O17: =SUM(K17:N17) -> 3712
C18: O | E18: O | F18: 10 | G18: SRK100ZR-W | H18: FDC100VSA-W | J18: бездротовий у комплекті | K18: =K14 -> 1105 | L18: 2772 | O18: =SUM(K18:N18) -> 3877
C19: Standard Inverter
C20: O | D20: O | F20: 7.1 | G20: SRK71ZR-W | H20: FDC71VNP-W | J20: бездротовий у комплекті | K20: =K13 -> 992 | L20: 1586 | O20: =SUM(K20:N20) -> 2578
C21: O | D21: O | F21: 10 | G21: SRK100ZR-W | H21: FDC100VNP-W | J21: бездротовий у комплекті | K21: =K14 -> 1105 | L21: 2214 | O21: =SUM(K21:N21) -> 3319
C22: Аксесуари | G22: RC-E5, дротовий пульт (підключення через SC-BIKN2-E) | O22: 104
G23: RCH-E3, дротовий пульт спрощений для готелів | O23: 145
G24: RC-EX3A, дротовий пульт із сенсорним керуванням, функції ротації та резервування (підключення через SC-BIKN2-E) | O24: 204
G25: RC-ES1, дротовий пульт чорного кольору, з Bluetooth® для підключення телефону програмою M-Air PRO | O25: 240
G26: SC-BIKN2-E, адаптер для підключення дротовий пульта, для реалізації керування за зовнішнім сигналом | O26: 133
G27: AM-MHI-01, Wi-Fi-адаптер (арт. INAWMMHI001/000) | O27: 114
B28: Стельові
B29: Стельові FDE | C29: Hyper Inverter
C30: O | D30: O | F30: 4 | G30: FDE40VH | H30: SRC40ZSX-W1 | J30: Дротовий RC-E5 інші пульти див. аксесуари | K30: 1083 | L30: 1309 | N30: =O22 -> 104 | O30: =SUM(K30:N30) -> 2496
C31: O | D31: O | F31: 6 | G31: FDE50VH | H31: SRC50ZSX-W2(3) | K31: 1095 | L31: 1620 | N31: =O22 -> 104 | O31: =SUM(K31:N31) -> 2819
C32: O | D32: O | F32: 5.6 | G32: FDE60VH | H32: SRC60ZSX-W1(3) | K32: 1122 | L32: 1715 | N32: =O22 -> 104 | O32: =SUM(K32:N32) -> 2941
C33: O | D33: O | F33: 7.1 | G33: FDE71VH | H33: FDC71VNX-W | K33: 1214 | L33: =L13 -> 2148 | N33: =O22 -> 104 | O33: =SUM(K33:N33) -> 3466
C34: O | D34: O | F34: 10 | G34: FDE100VH | H34: FDC100VNX-W | K34: 1502 | L34: =L14 -> 3271 | N34: =O22 -> 104 | O34: =SUM(K34:N34) -> 4877
C35: O | E35: O | F35: 10 | G35: FDE100VH | H35: FDC100VSX-W | K35: =K34 -> 1502 | L35: =L15 -> 3680 | N35: =O22 -> 104 | O35: =SUM(K35:N35) -> 5286
C36: O | D36: O | F36: 12.5 | G36: FDE125VH | H36: FDC125VNX-W | K36: 1613 | L36: 3836 | N36: =O22 -> 104 | O36: =SUM(K36:N36) -> 5553
C37: O | E37: O | F37: 12.5 | G37: FDE125VH | H37: FDC125VSX-W | K37: =K36 -> 1613 | L37: 4135 | N37: =O22 -> 104 | O37: =SUM(K37:N37) -> 5852
C38: O | D38: O | F38: 14 | G38: FDE140VH | H38: FDC140VNX-W | K38: 1744 | L38: 4067 | N38: =O22 -> 104 | O38: =SUM(K38:N38) -> 5915
C39: O | E39: O | F39: 14 | G39: FDE140VH | H39: FDC140VSX-W | K39: =K38 -> 1744 | L39: 4844 | N39: =O22 -> 104 | O39: =SUM(K39:N39) -> 6692
C40: Micro Inverter
...

Sheet HeatGuard
B7: Прайс HeatGuard 01.07.2023
A8: Таблиця підбору теплових насосів HeatGuard на основі зовнішніх блоків MHI Micro Inverter
A9: МОДЕЛЬ | B9: Внутрішній блок | C9: Розміри внутрішнього блоку ВхШхГ (мм) | D9: Зовнішній блок | E9: Розміри зовнішнього блоку ВхШхГ (мм) | F9: Наявність циркуляційного насосу | G9: Пульт ДK | H9: Теплопродуктивність / Холодопродуктивність кВт | I9: Вартість, Євро
A10: HeatGuard 300S | B10: HРМ 300 | C10: 702х400х395 | D10: HPC300VS | E10: 1505х970х370 | F10: + | G10: В комплекті | H10: 30,0/27,0 | I10: 10455
A11: Таблиця підбору теплових насосів "каскад" HeatGuard на базі зовнішніх блоків MHI Micro Inverter
A12: МОДЕЛЬ | B12: Внутрішній блок | C12: Розміри внутрішнього блоку ВхШхГ (мм) | D12: Зовнішній блок | E12: Розміри зовнішнього блоку ВхШхГ (мм) | F12: Наявність циркуляційного насосу | G12: Пульт ДK | H12: Теплопродуктивність / Холодопродуктивність кВт | I12: Вартість,Євро
A13: HeatGuard 300SМ | B13: HPM 300 М (ведучий) | C13: 702х400х395 | D13: HPC300VS | E13: 1505х970х370 | F13: + | G13: В комплекті | H13: 30,0/27,0 | I13: за запитом
A14: HeatGuard 300SС | B14: HPM 300 С (ведений) | C14: 702х400х395 | D14: HPC300VS | E14: 1505х970х370 | F14: + | G14: - | H14: 30,0/27,0 | I14: за запитом
A17: Таблиця підбору теплових насосів HeatGuard на базі зовнішніх блоків MHI Hyper Inverter
A18: МОДЕЛЬ | B18: Внутрішній блок | C18: Розміри внутрішнього блоку ВхШхГ (мм) | D18: Зовнішній блок | E18: Розміри зовнішнього блоку ВхШхГ (мм) | F18: Наявність циркуляційного насосу | G18: Пульт ДK | H18: Теплопродуктивність кВт | I18: Вартість, Євро | J18: У комплектацію блоку HPM входить:
A19: HeatGuard 60NX | B19: HPM 45-80 | C19: 702х414х308 | D19: HPC60VNX | E19: 640х800(+71)х290 | F19: + | G19: В комплекті | H19: 6,7 | I19: 4455 | J19: 1. Розширений функціонал (управління насосними групами (ГВП, басейн), можливість оновлення програмного забезпечення через інтернет, логування всіх параметрів на флеш-карту, погодозалежне регулювання, оптимізація роботи системи опалення з точки зору фінансової та енергетичної ефективності, добовий та тижневий графік роботи, можливість інтеграції в систему «розумний дім») 2. Віддалений доступ 3. Можливість поєднувати блоки в каскад до 16 шт. 4. Одночасна робота каскадної системи на охолодження та нагрівання води для ГВП 5. Енергоефективний інверторний циркуляційний насос внутрішнього блоку 6. Автоматичне блокування функції ГВП під час роботи сонячного колектора
A20: HeatGuard 80NX | B20: HPM 45-80 | C20: 702х414х308 | D20: HPC80VNX | E20: 750х880(+88)х340 | F20: + | G20: В комплекті | H20: 8,0 | I20: 4800
A21: HeatGuard 110NX | B21: HPM 110-160 | C21: 702х414х308 | D21: HPC110VNX | E21: 1300х970х370 | F21: + | G21: В комплекті | H21: 11,2 | I21: 6100
A22: HeatGuard 110SX | B22: HPM 110-160 | C22: 702х414х308 | D22: HPC110VSX | E22: 1300х970х370 | F22: + | G22: В комплекті | H22: 11,2 | I22: 6250
A23: HeatGuard 140NX | B23: HPM 110-160 | C23: 702х414х309 | D23: HPC140VNX | E23: 1300х970х371 | F23: + | G23: В комплекті | H23: 14,0 | I23: 6850
A24: HeatGuard 140SX | B24: HPM 110-160 | C24: 702х414х308 | D24: HPC140VSX | E24: 1300х970х370 | F24: + | G24: В комплекті | H24: 14,0 | I24: 7050
A25: HeatGuard 160NX | B25: HPM 110-160 | C25: 702х414х308 | D25: HPC160VNX | E25: 1300х970х370 | F25: + | G25: В комплекті | H25: 16,0 | I25: 7600
A26: HeatGuard 160SX | B26: HPM 110-160 | C26: 702х414х308 | D26: HPC160VSX | E26: 1300х970х370 | F26: + | G26: В комплекті | H26: 16,0 | I26: 7800
A28: Таблиця підбору теплових насосів "каскад" HeatGuard на базі зовнішніх блоків MHI Hyper Inverter
A29: МОДЕЛЬ | B29: Внутрішній блок | C29: Розміри внутрішнього блоку ВхШхГ (мм) | D29: Зовнішній блок | E29: Розміри зовнішнього блоку ВхШхГ (мм) | F29: Наявність циркуляційного насосу | G29: Пульт ДK | H29: Теплопродуктивність / Холодопродуктивність кВт | I29: Вартість,Євро
A30: HeatGuard 110NXМ | B30: HPM 110-160 МР (ведучий) | C30: 702х414х308 | D30: HPC110VNX | E30: 1300х970х370 | F30: + | G30: В комплекті | H30: 11,2 /10,0 | I30: за запитом
A31: HeatGuard 110SXМ | B31: HPM 110-160 МР (ведучий) | C31: 702х414х308 | D31: HPC110VSX | E31: 1300х970х370 | F31: + | G31: В комплекті | H31: 11,2 /10,0 | I31: за запитом
A32: HeatGuard 140SXМ | B32: HPM 110-160 МР (ведучий) | C32: 702х414х308 | D32: HPC140VSX | E32: 1300х970х370 | F32: + | G32: В комплекті | H32: 14,0 /12,5 | I32: за запитом
A33: HeatGuard 160SXМ | B33: HPM 110-160 МР (ведучий) | C33: 702х414х308 | D33: HPC160VSX | E33: 1300х970х370 | F33: + | G33: В комплекті | H33: 16,0 /14,0 | I33: за запитом
A34: HeatGuard 110NXС | B34: HPM 110-160 СР (ведений) | C34: 702х414х308 | D34: HPC110VNX | E34: 1300х970х370 | F34: + | H34: 11,2 /10,0 | I34: за запитом
A35: HeatGuard 110SXС | B35: HPM 110-160 СР (ведений) | C35: 702х414х308 | D35: HPC110VSX | E35: 1300х970х370 | F35: + | H35: 11,2 /10,0 | I35: за запитом
A36: HeatGuard 140SXС | B36: HPM 110-160 СР (ведений) | C36: 702х414х308 | D36: HPC140VSX | E36: 1300х970х370 | F36: + | H36: 14,0 /12,5 | I36: за запитом
A37: HeatGuard 160SXС | B37: HPM 110-160 СР (ведений) | C37: 702х414х308 | D37: HPC160VSX | E37: 1300х970х370 | F37: + | H37: 16,0 /14,0 | I37: за запитом
A38: Таблиця підбору безкорпусних теплових насосів HeatGuard на базі зовнішніх блоків MHI Hyper Inverter
A39: МОДЕЛЬ | B39: Внутрішній блок | C39: Розміри внутрішнього блоку ВхШхГ (мм) | D39: Зовнішній блок | E39: Розміри зовнішнього блоку ВхШхГ (мм) | F39: Наявність циркуляційного насосу | G39: Пульт ДK | H39: Теплопродуктивність / Холодопродуктивність кВт | I39: Вартість, Євро
A40: HeatGuard 220NX | B40: HPМТ220-320 (Двоконтурний, можлива комплектація зовнішніми блоками різної теплопродуктивності кожного контуру) | D40: HPC110VNX - 2шт | E40: 1300х970х370 | F40: + | G40: В комплекті | H40: 22,4 /20,0 | I40: за запитом
A41: HeatGuard 220SX | D41: HPC110VSX - 2шт | E41: 1300х970х370 | F41: + | G41: В комплекті | H41: 22,4 /20,0 | I41: за запитом
A42: HeatGuard 280SX | D42: HPC140VSX - 2шт | E42: 1300х970х370 | F42: + | G42: В комплекті | H42: 28,0 /25,0 | I42: за запитом
A43: HeatGuard 320SX | D43: HPC160VSX - 2шт | E43: 1300х970х370 | F43: + | G43: В комплекті | H43: 32,0 28,0 | I43: за запитом
A44: Таблиця підбору безкорпусних теплових насосів "каскад" HeatGuard на базі зовнішніх блоків MHI Hyper Inverter
A45: МОДЕЛЬ | B45: Внутрішній блок | C45: Розміри внутрішнього блоку ВхШхГ (мм) | D45: Зовнішній блок | E45: Розміри зовнішнього блоку ВхШхГ (мм) | F45: Наявність циркуляційного насосу | G45: Пульт ДK | H45: Теплопродуктивність / Холодопродуктивність кВт | I45: Вартість,Євро | J45: Фото
A46: HeatGuard 220NX | B46: HPМТ220-320М (Двоконтурний, можлива комплектація зовнішніми блоками різної теплопродуктивності кожного контуру) | D46: HPC110VNX - 2шт | E46: 1300х970х370 | F46: + | G46: В комплекті | H46: 22,4 /20,0 | I46: за запитом
A47: HeatGuard 220SX | D47: HPC110VSX - 2шт | E47: 1300х970х370 | F47: + | G47: В комплекті | H47: 22,4 /20,0 | I47: за запитом
A48: HeatGuard 280SX | D48: HPC140VSX - 2шт | E48: 1300х970х370 | F48: + | G48: В комплекті | H48: 28,0 /25,0 | I48: за запитом
A49: HeatGuard 320SX | D49: HPC160VSX - 2шт | E49: 1300х970х370 | F49: + | G49: В комплекті | H49: 32,0 28,0 | I49: за запитом
...

Sheet WineGuard
A1: з 01.02.2025
A3: МОДЕЛЬ | B3: ТИП БЛОКУ | C3: НАЙМЕНУВАННЯ БЛОКУ | D3: ГАБАРИТИ, мм | E3: ВАГА, кг | F3: Споживча потужність, кВт. | G3: Діаметр Труб Рід./газ мм. | H3: ПРОДУКТИВНІСТЬ, Вт (при tвн.+10 tзов.+35 С) | I3: Діапазон регулювання температури в камері, С | J3: Діапазон температури ззовні, С | K3: Зволоження | L3: Підміс свіжого повітря | M3: Характеристики мережі ел. живлення | N3: РОЗДРІБНА ВАРТІСТЬ КОМПЛЕКТУ, $*
A4: НАСТІННА КЛІМАТИЧНА СИСТЕМА "WINEGUARD"
A5: MT 20Н | B5: внутрішній | C5: MHI SRK25ZS-W | D5: 290х870х230 | E5: 9.5 | F5: 0.62 | G5: 6,35/9,52 | H5: 2050 | I5: +7 - +30 | J5: -25 - +40 | K5: Відсутнє | L5: Відсутнє | M5: 1 фаза, 220-240В, 50 Гц | N5: 2300
B6: зовнішній | C6: MHI SRC25ZS-W | D6: 540х780(+62)х290 | E6: 31
A7: MT 30Н | B7: внутрішній | C7: MHI SRK35ZS-W | D7: 290х870х230 | E7: 9.5 | F7: 0.89 | H7: 2900 | N7: 2600
B8: зовнішній | C8: MHI SRC35ZS-W | D8: 540х780(+62)х290 | E8: 34.5
A9: MT 40Н | B9: внутрішній | C9: MHI SRK50ZS-W | D9: 290х870х230 | E9: 10 | F9: 1.35 | G9: 6,35/12,7 | H9: 4100 | N9: 2900
B10: зовнішній | C10: MHI SRC50ZS-W | D10: 595х780(+62)х290 | E10: 36
A11: КАНАЛЬНА КЛІМАТИЧНА СИСТЕМА "WINEGUARD"
A12: MT 20К | B12: внутрішній | C12: MHI SRR25ZS-W | D12: 200х750х500 | E12: 20.5 | F12: 0.62 | G12: 6,35/9,52 | H12: 2050 | I12: =I5 -> +7 - +30 | J12: =J5 -> -25 - +40 | K12: Опція | M12: =M5 -> 1 фаза, 220-240В, 50 Гц | N12: 3400
B13: зовнішній | C13: MHI SRC25ZS-W | D13: 540х780(+62)х290 | E13: 31
A14: MT 30К | B14: внутрішній | C14: MHI SRR35ZS-W | D14: 200х750х500 | E14: 20.5 | F14: 0.93 | H14: 2900 | N14: 3800
B15: зовнішній | C15: MHI SRC35ZS-W | D15: 540х780(+62)х290 | E15: 34.5
A16: MT 40К | B16: внутрішній | C16: MHI FDUM50VH | D16: 280х750х635 | E16: 29 | F16: 1.35 | G16: 6,35/12,7 | H16: 4100 | N16: 4200
B17: зовнішній | C17: MHI SRC50ZS-W | D17: 595х780(+62)х290 | E17: 36
A18: MT 60К | B18: внутрішній | C18: MHI FDUM71VH | D18: 280х950х635 | E18: 34 | F18: 1.77 | G18: 9,52/15,88 | H18: 5820 | N18: 4600
B19: зовнішній | C19: MHI FDC71VNX-W | D19: 750x880(+88)x340 | E19: 60
A20: MT 80К | B20: внутрішній | C20: MHI FDUM100VH | D20: 280х1370х740 | E20: 54 | F20: 2.99 | H20: 8200 | N20: 5000
B21: зовнішній | C21: MHI FDC100VNA-W | D21: 845х970х370 | E21: 78
A22: MT 100К | B22: внутрішній | C22: MHI FDUM125VH | D22: 280х1370х740 | E22: 54 | F22: 4.36 | H22: 10250 | N22: 5500
B23: зовнішній | C23: MHI FDC125VNA-W | D23: 845х970х370 | E23: 78
A24: MT 120К | B24: внутрішній | C24: MHI FDUM140VH | D24: 280х1370х740 | E24: 54 | F24: 5.13 | H24: 11480 | N24: 6500
B25: зовнішній | C25: MHI FDC140VNA-W | D25: 845х970х370 | E25: 78
A26: MT 160К | B26: внутрішній | C26: MHI FDU200VH | D26: 379х1600х893 | E26: 88 | F26: 6.15 | G26: 9,52/22,22 | H26: 16400 | M26: 3 фазы, 380-415В, 50 Гц | N26: 11800
B27: зовнішній | C27: MHI FDC200VSA-W | D27: 1505х970х370 | E27: 144
A28: MT 200К | B28: внутрішній | C28: MHI FDU250VH | D28: 379х1600х893 | E28: 88 | F28: 8.25 | G28: 12,7/22,22 | H28: 20500 | N28: 12500
B29: зовнішній | C29: MHI FDC250VSA-W | D29: 1505х970х370 | E29: 145
A30: Діапазон температур°С: в камері +7 ~ +18; зовні - 25 ~ + 40 Холодоагент R32
A31: ДЛЯ ВИКОНАННЯ УМОВ ГАРАНТІЇ ПОТРІБЕН ОДНОКРАТНИЙ ПОВІТРООБМІН ДВА РАЗИ НА ДОБУ - НАЯВНІСТЬ ПРИМУСОВОЇ ВЕНТИЛЯЦІЇ ТА ВІЛЬНИЙ ДОСТУП ПОВІТРЯ В ПРИМІЩЕННІ ДЛЯ ГАРАНТОВАНОГО ПОВІТРООБМІНУ - ОБОВЯЗКОВО!
A32: КАНАЛЬНА КЛІМАТИЧНА СИСТЕМА "WINEGUARD" ЗІ ЗВОЛОЖЕННЯМ - ОПЦІЯ
A33: МОНТАЖ, ДОСТАВКА, СЕРВІСНЕ ОБСЛУГОВУВАННЯ, ГАРАНТІЯ
A34: У вартість комплекту входить доставка обладнання по Україні
A35: Гарантія 3 роки, монтаж тільки спеціалістами інженерної компанії "ІВІК"
A36: Сервісне обслуговування для даного обладнання необхідно 2 рази на рік.
A37: * оплата здійснюється в грн по комерційному курсу на день оплати

Sheet GALACTIC
M4: =ГОЛОВНА!Q11 -> 44
B6: МОДЕЛЬ | C6: ТИП БЛОКУ | D6: НАЙМЕНУВАННЯ БЛОКУ | E6: ПРОДУКТИВНІСТЬ | F6: Споживана потужність | G6: Коефіцієнт ефективності | I6: МІЦ, грн. | K6: Ціна дилер у.е., у.е.=$
E7: Охолодження, Вт | F7: Охолодження, Вт | G7: SEER / EER (холод)
E8: Нагрів, Вт | F8: Нагрів, Вт | G8: SCOP / COP (тепло)
B9: Спліт-системи настінного типу інверторні (холод-тепло)
B10: Моделі INFINI INVERTER Фреон R32. Клас енергоефективності охолодження "А+++", клас енергоефективності нагрів "А++", функція "I Feel", керування горизонтальними та вертикальними жалюзі з ПДУ, захист від стрибків напруги, самодіагностика, самоочищення, 24-годинний таймер, авторестарт, генератор негативних іонів, WI-FI, Compount фільтр. Golden Fin. Підігрів картера компресора та піддону. Електронний ТРВ. Компресор подвійного стискування. Робота на обігрів при температурі -30°С.
B11: МОДЕЛЬ INFINI | C11: ТИП БЛОКУ | D11: НАЙМЕНУВАННЯ БЛОКУ | E11: Продуктивність, кВт | F11: Споживана потужність, кВт | G11: SEER / EER; SCOP / COP | I11: МІЦ, грн. | K11: Ціна дилер у.е., у.е.=$
B12: GKZ09SH-W | C12: внутр. | D12: GKZ09SH-W | E12: 2.64 (0.82~3.66) | F12: 0.58 (0.06~1.2) | G12: 8.5 / 4.57 | I12: =SUM(K12)/0.8*$M$4 -> 36300 | K12: 660 | L12: 156
C13: зовніш. | D13: GCZ09SH-W | E13: 2.93 (0.79~4.39) | F13: 0.62 (0.07~1.4) | G13: 4.6 / 4.7 | L13: 504
B14: GKZ09SH-WS | C14: внутр. | D14: GKZ09SH-WS | E14: 2.64 (0.82~3.66) | F14: 0.58 (0.06~1.2) | G14: 8.5 / 4.57 | I14: =SUM(K14)/0.8*$M$4 -> 36300 | K14: 660 | L14: 156
B15: срібляста смуга | C15: зовніш. | D15: GCZ09SH-W | E15: 2.93 (0.79~4.39) | F15: 0.62 (0.07~1.4) | G15: 4.6 / 4.7 | L15: 504
B16: GKZ12SH-W | C16: внутр. | D16: GKZ12SH-W | E16: 3.52 (0.88~4.75) | F16: 0.88 (0.60~1.6) | G16: 8.1 / 4.0 | I16: =SUM(K16)/0.8*$M$4 -> 38500 | K16: 700 | L16: 175
C17: зовніш. | D17: GCZ12SH-W | E17: 3.81 (0.79~5.57) | F17: 0.93 (0.13~2.1) | G17: 4.6 / 4.1 | L17: 525
B18: GKZ12SH-WS | C18: внутр. | D18: GKZ12SH-WS | E18: 3.52 (0.88~4.75) | F18: 0.88 (0.60~1.6) | G18: 8.1 / 4.0 | I18: =SUM(K18)/0.8*$M$4 -> 38500 | K18: 700 | L18: 175
B19: срібляста смуга | C19: зовніш. | D19: GCZ12SH-W | E19: 3.81 (0.79~5.57) | F19: 0.93 (0.13~2.1) | G19: 4.6 / 4.1 | L19: 525
B20: Моделі VEGA INVERTER Фреон R32. Клас енергоефективності "А++", функція "I Feel", керування горизонтальними та вертикальними жалюзі з ПДУ, захист від стрибків напруги, самодіагностика, самоочищення, 24-годинний таймер, авторестарт, WI-FI ready, Golden Fin. Робота на обігрів при температурі -15°С.
B21: МОДЕЛЬ VEGA | C21: ТИП БЛОКУ | D21: НАЙМЕНУВАННЯ БЛОКУ | E21: Продуктивність, кВт | F21: Споживана потужність, кВт | G21: SEER / SCOP | I21: МІЦ, грн. | K21: Ціна дилер у.е., у.е.=$
B22: GKZ07A-W | C22: внутр. | D22: GKZ07A-W | E22: 2.6 (0.6~3.1) | F22: 0.85 (0.1~1.6) | G22: 6.40 | I22: =SUM(K22)/0.8*$M$4 -> 13640 | K22: 248 | L22: =SUM(K22)*0.3 -> 74.4 | M22: !Без додаткових знижок!
C23: зовніш. | D23: GCZ07A-W | E23: 2.61 (0.8~3.4) | F23: 0.63 (0.3~1.6) | G23: 4.00 | L23: =SUM(K22)*0.7 -> 173.6
B24: GKZ09A-W | C24: внутр. | D24: GKZ09A-W | E24: 2.65 (0.6~3.1) | F24: 0.81 (0.1~1.6) | G24: 6.50 | I24: =SUM(K24)/0.8*$M$4 -> 18150 | K24: 330 | L24: =SUM(K24)*0.3 -> 99
C25: зовніш. | D25: GCZ09A-W | E25: 2.7 (0.8~3.4) | F25: 0.72 (0.3~1.5) | G25: 4.00 | L25: =SUM(K24)*0.7 -> 231
B26: GKZ12A-W | C26: внутр. | D26: GKZ12A-W | E26: 3.4 (0.8~3.8) | F26: 1.34 (0.2~1.5) | G26: 6.20 | I26: =SUM(K26)/0.8*$M$4 -> 21450 | K26: 390 | L26: =SUM(K26)*0.3 -> 117
C27: зовніш. | D27: GCZ12A-W | E27: 3.5 (0.8~4.0) | F27: 0.95 (0.2~1.4) | G27: 4.00 | L27: =SUM(K26)*0.7 -> 273
B28: GKZ18A-W | C28: внутр. | D28: GKZ18A-W | E28: 5.1 (1.3~5.3) | F28: 1.67 (0.28~1.8) | G28: 6.70 | I28: =SUM(K28)/0.8*$M$4 -> 27060 | K28: 492 | L28: =SUM(K28)*0.3 -> 147.6 | M28: !Без додаткових знижок!
C29: зовніш. | D29: GCZ18A-W | E29: 5.2 (1.3~5.3) | F29: 1.4 (0.22~1.5) | G29: 4.00 | L29: =SUM(K28)*0.7 -> 344.4
B30: GKZ24A-W | C30: внутр. | D30: GKZ24A-W | E30: 7.3 (1.8~7.4) | F30: 2.2 (0.23~2.76) | G30: 6.53 | I30: =SUM(K30)/0.8*$M$4 -> 36960 | K30: 672 | L30: =SUM(K30)*0.3 -> 201.6 | M30: !Без додаткових знижок!
C31: зовніш. | D31: GCZ24A-W | E31: 7.3 (1.8~8.0) | F31: 2.2 (0.23~2.53) | G31: 4.00 | L31: =SUM(K30)*0.7 -> 470.4
B32: Wi-Fi модуль для GKZ-A-W | C32: Модуль безпровідного керування для GKZ-A-W | F32: Додаткові знижки на цю позицію не передбачені! | I32: =SUM(K32)/0.8*$M$4 -> 1100 | K32: 20 | L32: =SUM(K32)*0.3 -> 6
L33: =SUM(K32)*0.7 -> 14
B34: Моделі Proxima INVERTER Фреон R32. Клас енергоефективності "А+", функція "I Feel", керування горизонтальними та вертикальними жалюзі з ПДУ, захист від стрибків напруги, самодіагностика, самоочищення, 24-годинний таймер, авторестарт, генератор негативних іонів, WI-FI ready, Compount фільтр. Golden Fin. Робота на обігрів при температурі -15°С.
B35: МОДЕЛЬ PROXIMA | C35: ТИП БЛОКУ | D35: НАЙМЕНУВАННЯ БЛОКУ | E35: Продуктивність, Вт | F35: Споживана потужність, Вт | G35: EER / COP | I35: МІЦ, грн. | K35: Ціна дилер у.е., у.е.=$
B36: GKZ07M-W | C36: внутр. | D36: GKZ07M-W | E36: 2346 (1170~2950) | F36: 730 (100~1074) | G36: 3.21 | I36: =SUM(K36)/0.8*$M$4 -> 17325 | K36: 315 | L36: =SUM(K36)*0.3 -> 94.5
C37: зовніш. | D37: GCZ07M-W | E37: 2430 (910~2991) | F37: 670 (140~896) | G37: 3.63 | L37: =SUM(K36)*0.7 -> 220.5
B38: GKZ09M-W | C38: внутр. | D38: GKZ09M-W | E38: 2630 (1170~2950) | F38: 823 (100~1074) | G38: 3.21 | I38: =SUM(K38)/0.8*$M$4 -> 18150 | K38: 330 | L38: =SUM(K38)*0.3 -> 99
C39: зовніш. | D39: GCZ09M-W | E39: 2930 (910~2991) | F39: 812 (140~896) | G39: 3.61 | L39: =SUM(K38)*0.7 -> 231
B40: GKZ12M-W | C40: внутр. | D40: GKZ12M-W | E40: 3607 (1290~3784) | F40: 1123 (280~1220) | G40: 3.21 | I40: =SUM(K40)/0.8*$M$4 -> 21450 | K40: 390 | L40: =SUM(K40)*0.3 -> 117
C41: зовніш. | D41: GCZ12M-W | E41: 3710 (1056~4048) | F41: 1028 (300~1260) | G41: 3.61 | L41: =SUM(K40)*0.7 -> 273
B42: GKZ18M-W | C42: внутр. | D42: GKZ18M-W | E42: 5279 (1818~6159) | F42: 1550 (140~2300) | G42: 3.40 | I42: =SUM(K42)/0.8*$M$4 -> 38500 | K42: 700 | L42: =SUM(K42)*0.3 -> 210
C43: зовніш. | D43: GCZ18M-W | E43: 5573 (1290~6746) | F43: 1570 (220~2350) | G43: 3.61 | L43: =SUM(K42)*0.7 -> 490
B44: GKZ24M-W | C44: внутр. | D44: GKZ24M-W | E44: 7039 (2082~7919) | F44: 2600 (420~3150) | G44: 2.81 | I44: =SUM(K44)/0.8*$M$4 -> 51700 | K44: 940 | L44: =SUM(K44)*0.3 -> 282
...

Sheet Galactic LCAC
K2: =ГОЛОВНА!Q11 -> 44
B3: МОДЕЛЬ | C3: ТИП БЛОКУ | D3: ПРОДУКТИВНІСТЬ, Вт | E3: Споживана потужність, Вт | F3: EER /COP (SEER /SCOP) | G3: Магістраль | I3: Ціна дилер у.е., у.е.=$
B4: LCAC - серія, холодоагент R32 INVERTER
B5: Моделі LCAC INVERTER Клас енергоефективності "А++", автоматичний перезапуск, функція самодіагностики несправності, 24-годинний таймер УВІМ. та ВИМК. Можливість підмішування свіжого повітря. Захист від стрибків напруги. Підігрів картера та дренажу. Можливість керування через Wi-Fi (опція).
B6: Касетний
B7: МОДЕЛЬ | C7: ТИП БЛОКУ | D7: ПРОДУКТИВНІСТЬ, кВт | E7: Споживана потужність, кВт | F7: SEER /SCOP | G7: Магістраль | I7: Ціна дилер у.е., у.е.=$
B8: GBZ18MLQ-W | C8: внутр.+пульт ІЧ | D8: 5.27(2.9~5.59) | E8: 1.633(0.720~2.088) | F8: 6,1/4 | G8: d 1/4"/1/2" | I8: 1040 | J8: 330.15873
B9: PM-GBZ18 | C9: панель | J9: 41.269841
B10: GCZ18MLNQ-W | C10: зовніш. | D10: 5.57(2.376~6.1) | E10: 1.540(0.700~1.930) | G10: L/H 30/20 | J10: 668.57143
B11: GBZ18MLQ7-W | C11: внутр.+пульт ІЧ | D11: 5.27(2.9~5.59) | E11: 1,55 (0,72~2,04) | F11: 6,5/4,1 | G11: d 1/4"/1/2" | I11: 1040 | J11: 330.15873
B12: PM-GBZ18/7 | C12: панель | J12: 41.269841
B13: GCZ18MLNQ-W | C13: зовніш. | D13: 5.57(2.37~6.3) | E13: 1,56 (0,70~1,95) | G13: L/H 30/20 | J13: 668.57143
B14: GBZ24MLQ-W | C14: внутр.+пульт ІЧ | D14: 7.04(3.3~7.919) | E14: 2.191(0.780~2.748) | F14: 6,1/4 | G14: d 3/8"/5/8" | I14: 1300 | J14: 394
B15: PM-GBZ24-60Q | C15: панель | J15: 52
B16: GCZ24MLNQ-W | C16: зовніш. | D16: 7.626(2.809~8.946) | E16: 1.9(0.61~2.70) | G16: L/H 50/25 | J16: 854
B17: GBZ24MLQ-W | C17: внутр.+пульт ІЧ | D17: 7,03 (3,30~7,91) | E17: 2,19 (0,78~2,75) | F17: 6,3/4,1 | G17: d 3/8"/5/8" | I17: 1300 | J17: 394
B18: PM-GBZ24-60Q | C18: панель | J18: 52
B19: GCZ24MLNQ7-W | C19: зовніш. | D19: 7,62 (2,78~8,50) | E19: 1,90 (0,61~2,30) | G19: L/H 50/25 | J19: 854
B20: GBZ36MLQ-W | C20: внутр.+пульт ІЧ | D20: 10.56(2.7~11.44) | E20: 3.755(0.90~4.2) | F20: 6,1/4 | G20: d 3/8"/5/8" | I20: 1690 | J20: 485
B21: PM-GBZ24-60Q | C21: панель | J21: 52
B22: GCZ36MLNQ-W | C22: зовніш. | D22: 11.15(2.79~12.32) | E22: 3.0(0.78~4.00) | G22: L/H 75/30 | J22: 1153
B23: GBZ36MLQ-W | C23: внутр.+пульт ІЧ | D23: 10.56(2.7~11.44) | E23: 3.755(0.90~4.2) | F23: 6,1/4 | G23: d 3/8"/5/8" | I23: 1865 | J23: 485
B24: PM-GBZ24-60Q | C24: панель | J24: 52
B25: GCZ36MLSQ-W | C25: зовніш. | D25: 11.15(2.79~12.32) | E25: 3.0(0.78~4.00) | G25: L/H 75/30 | J25: 1328
B26: GBZ48ML(Q)-W | C26: внутр.+пульт ІЧ | D26: 14,08(3,52~15,84) | E26: 4,38(0,80~5,9) | F26: 6,1/4 | G26: d 3/8"/5/8" | I26: 2175 | J26: 738.73016
B27: PM-GBZ24-60Q | C27: панель | J27: 51.587302
B28: GCZ48MLS(Q)-W | C28: зовніш. | D28: 16,13(4,1~17,3) | E28: 4,465(0,9~5,5) | G28: L/H 75/30 | J28: 1384.6032
B29: GBZ60ML-W | C29: внутр.+пульт ІЧ | D29: 14,08(3,52~15,84) | E29: 4,38(0,80~5,9) | F29: 6,1/4 | G29: d 3/8"/5/8" | I29: 2265
B30: PM-GBZ24-60Q | C30: панель
B31: GCZ48MLS-W | C31: зовніш. | D31: 16,13(4,1~17,3) | E31: 4,465(0,9~5,5) | G31: L/H 75/30
B32: GBZ60ML(Q)-W | C32: внутр.+пульт ІЧ | D32: 16,13(4,11~16,7) | E32: 5,022(0,980~6,200) | F32: 6,1/4 | G32: d 3/8"/5/8" | I32: 2315 | J32: 786
B33: PM-GBZ24-60Q | C33: панель | J33: 51.587302
B34: GCZ60MLS(Q)-W1 | C34: зовніш. | D34: 18,18(4,40~19,94) | E34: 5,034(1,02~6,700) | G34: L/H 75/30 | J34: 1477.4603
B35: GBZ60MLQ-W | C35: внутр.+пульт ІЧ | D35: 15,68 (4,10~16,12) | E35: 5,58 (1,00~6,25) | F35: 6,1/4 | G35: d 3/8"/5/8" | I35: 2315 | J35: 786
B36: PM-GBZ24-60Q | C36: панель | J36: 51.587302
B37: GCZ60MLSQ7-W | C37: зовніш. | D37: 18,17 (4,40~19,05) | E37: 5,03 (1,02~6,35) | G37: L/H 75/30 | J37: 1477.4603
B39: Канальний
B41: GDZ18ML(Q)-W | C41: внутр.+пульт дротовий | D41: 5.3(2.55~5.87) | E41: 1.53(0.71~2.15) | F41: 6,1/4 | G41: d 1/4"/1/2" | I41: 1005 | J41: 336
B42: GCZ18MLN(Q)-W | C42: зовніш. | D42: 5.57(2.2~6.16) | E42: 1.51(0.74~1.76) | G42: L/H 30/20 | J42: 669
B43: GDZ18MLQ7-W | C43: внутр.+пульт дротовий | D43: 5,28 (1,32~6,15) | E43: 1,59 (0,36~2,13) | F43: 6,5/4,1 | G43: d 1/4"/1/2" | I43: 1005 | J43: 336
...

Sheet Galactic VRF
A2: Зовнішні блоки
A3: Фото | B3: МОДЕЛЬ | C3: Продуктивність | F3: Споживана потужність | H3: EER /COP | I3: РРЦ, У.Е. | J3: Примітка
C4: к.с. | D4: Охолодження, кВт | E4: Нагрів, кВт | F4: Охолодження, кВт | G4: Нагрів, кВт
B5: GUC-76Z-SR | C5: 8HP | D5: 22.4 | E5: 25 | F5: 5.21 | G5: 5.77 | H5: 4,3/4,33 | I5: За запитом | J5: S Heat Recovery Series (Full DC inverter, three pipe system ) VRF-3 pipe
B6: GUC-96Z-SR | C6: 10HP | D6: 28 | E6: 31.5 | F6: 7 | G6: 7.59 | H6: 4/4,15 | I6: За запитом
B7: GUC-114Z-SR | C7: 12HP | D7: 33.5 | E7: 37.5 | F7: 8.65 | G7: 9.21 | H7: 3,87/4,07 | I7: За запитом
B8: GUC-136Z-SR | C8: 14HP | D8: 40 | E8: 45 | F8: 10.53 | G8: 11.72 | H8: 3,8/3,84 | I8: За запитом
B9: GUC-154Z-SR | C9: 16HP | D9: 45 | E9: 50 | F9: 12.5 | G9: 13.7 | H9: 3,6/3,65 | I9: За запитом
B10: GUC-170Z-SR | C10: 18HP | D10: 50 | E10: 56 | F10: 15.63 | G10: 16.97 | H10: 3,2/3,3 | I10: За запитом
B11: GUC-190Z-SR | C11: 20HP | D11: 56 | E11: 63 | F11: 17.9 | G11: 19.87 | H11: 3,13/3,17 | I11: За запитом
B12: GUC-212Z-SR | C12: 22HP | D12: 61.5 | E12: 69 | F12: 20.5 | G12: 22.48 | H12: 3/3,07 | I12: За запитом
B13: GUC-232Z-SR | C13: 24HP | D13: 68 | E13: 75 | F13: 22.82 | G13: 24.59 | H13: 2,98/3,05 | I13: За запитом
B14: GUC-250Z-SR | C14: 26HP | D14: 72.5 | E14: 80 | F14: 24.58 | G14: 26.67 | H14: 2,95/3 | I14: За запитом
B15: GUC-272Z-SR | C15: 28HP | D15: 80 | E15: 90 | F15: 27.59 | G15: 30.41 | H15: 2,9/2,96 | I15: За запитом
B16: GUC-76Z-H | C16: 8HP | D16: 22.4 | E16: 25 | F16: 5.25 | G16: 5.62 | H16: 4,27/4,45 | I16: За запитом | J16: Full DC inverter 380-415V/3PH/50HZ
B17: GUC-96Z-H | C17: 10HP | D17: 28 | E17: 31.5 | F17: 7.31 | G17: 7.61 | H17: 3,83/4,14 | I17: За запитом
B18: GUC-114Z-H | C18: 12HP | D18: 33.5 | E18: 37.5 | F18: 8.57 | G18: 8.89 | H18: 3,91/4,22 | I18: За запитом
B19: GUC-136Z-H | C19: 14HP | D19: 40 | E19: 45 | F19: 11.05 | G19: 11.08 | H19: 3,62/4,06 | I19: За запитом
B20: GUC-154Z-H | C20: 16HP | D20: 45 | E20: 50 | F20: 13.16 | G20: 12.47 | H20: 3,42/4,01 | I20: За запитом
B21: GUC-76Z-SA | C21: 8HP | D21: 22.4 | E21: 25 | F21: 5.21 | G21: 5.77 | H21: 4,3/4,33 | I21: За запитом | J21: Full DC inverter 380-415V/3PH/50HZ New Generation cooling under 52℃ heating under -25℃
B22: GUC-96Z-SA | C22: 10HP | D22: 28 | E22: 31.5 | F22: 7 | G22: 7.59 | H22: 4/4,15 | I22: За запитом
B23: GUC-114Z-SA | C23: 12HP | D23: 33.5 | E23: 37.5 | F23: 8.65 | G23: 9.21 | H23: 3,87/4,07 | I23: За запитом
B24: GUC-136Z-SA | C24: 14HP | D24: 40 | E24: 45 | F24: 10.53 | G24: 11.72 | H24: 3,8/3,84 | I24: За запитом
B25: GUC-154Z-SA | C25: 16HP | D25: 45 | E25: 50 | F25: 12.5 | G25: 13.7 | H25: 3,6/3,65 | I25: За запитом
B26: GUC-170Z-SA | C26: 18HP | D26: 50 | E26: 56 | F26: 15.63 | G26: 16.97 | H26: 3,2/3,3 | I26: За запитом
B27: GUC-190Z-SA | C27: 20HP | D27: 56 | E27: 63 | F27: 17.9 | G27: 19.87 | H27: 3,13/3,17 | I27: За запитом
B28: GUC-212Z-SA | C28: 22HP | D28: 61.5 | E28: 69 | F28: 20.5 | G28: 22.48 | H28: 3/3,07 | I28: За запитом
B29: GUC-232Z-SA | C29: 24HP | D29: 68 | E29: 75 | F29: 22.82 | G29: 24.59 | H29: 2,98/3,05 | I29: За запитом
B30: GUC-250Z-SA | C30: 26HP | D30: 72.5 | E30: 80 | F30: 24.58 | G30: 26.67 | H30: 2,95/3 | I30: За запитом
B31: GUC-272Z-SA | C31: 28HP | D31: 80 | E31: 90 | F31: 27.59 | G31: 30.41 | H31: 2,9/2,96 | I31: За запитом
B32: GUC-48Z-DSH2 | C32: 5HP | D32: 14 | E32: 16 | F32: 3.92 | G32: 4.03 | H32: 3,57/3,97 | I32: За запитом | J32: 380-415V/3PH/50HZ
B33: GUC-54Z-DSH2 | C33: 6HP | D33: 15.5 | E33: 18 | F33: 4.44 | G33: 4.74 | H33: 3,49/3,80 | I33: За запитом
B34: GUC-76Z-SH | C34: 8HP | D34: 22.4 | E34: 25 | F34: 6.36 | G34: 5.81 | H34: 3,52/4,30 | I34: За запитом
B35: GUC-96Z-SH | C35: 10HP | D35: 28 | E35: 31.5 | F35: 7.8 | G35: 7 | H35: 3,59/4,50 | I35: За запитом
B36: GUC-114Z-SH | C36: 12HP | D36: 33.5 | E36: 37.5 | F36: 10.6 | G36: 10.11 | H36: 3,16/3,71 | I36: За запитом
B37: GUC-38Z-DNH | C37: 4HP | D37: 11.2 | E37: 12.5 | F37: 2.6 | G37: 2.78 | H37: 4,31/4,50 | I37: За запитом | J37: 220-240V/1PH/50HZ
B38: GUC-48Z-DNH | C38: 5HP | D38: 14 | E38: 16 | F38: 3.46 | G38: 3.71 | H38: 4,05/4,31 | I38: За запитом
B39: GUC-54Z-DNH | C39: 6HP | D39: 15.5 | E39: 18 | F39: 4.21 | G39: 4.47 | H39: 3,68/4,03 | I39: За запитом
B40: GUC-28Z-NH | C40: 3HP | D40: 8 | E40: 9.5 | F40: 1.93 | G40: 2.37 | H40: 4,15/4,01 | I40: За запитом | J40: 220-240V/1PH/50HZ
B41: GUC-34Z-NH | C41: 4HP | D41: 10 | E41: 11.2 | F41: 2.34 | G41: 3.01 | H41: 4,27/3,72 | I41: За запитом
...

Sheet Galactic ККБ
B2: Фото | C2: МОДЕЛЬ | D2: Продуктивність к.с. | E2: Продуктивність | G2: Споживана потужність | I2: EER /COP | J2: РРЦ, У.Е. | K2: Примітка
E3: Охолодження, кВт | F3: Нагрів, кВт | G3: Охолодження, кВт | H3: Нагрів, кВт
B4: Компресорно-конденцаторний блок Galactiс: Спіральні FULL DC-інверторні компресори Mitsubishi Electric, двоступінчасте переохолодження, до 4-x зовнішніх блоків в єдиній системі, плавне регулювання продуктивності - вентилятори з DC-двигунами, авторестарт, подвійна система сепарації мастила (при об'єднанні не потрібні між блоками масловирівнювальні труби), інтелектуальне управління, компактні габарити.
C6: GUC-76Z-H | D6: 8HP | E6: 22.4 | F6: 25 | G6: 5.25 | H6: 5.62 | I6: 4,27/4,45 | J6: За запитом | K6: 380-415V 3PH/ 50HZ
C7: GUC-96Z-H | D7: 10HP | E7: 28 | F7: 31.5 | G7: 7.31 | H7: 7.61 | I7: 3,83/4,14 | J7: За запитом
C8: GUC-114Z-H | D8: 12HP | E8: 33.5 | F8: 37.5 | G8: 8.57 | H8: 8.89 | I8: 3,91/4,22 | J8: За запитом
C9: GUC-136Z-H | D9: 14HP | E9: 40 | F9: 45 | G9: 11.05 | H9: 11.08 | I9: 3,62/4,06 | J9: За запитом
C10: GUC-154Z-H | D10: 16HP | E10: 45 | F10: 50 | G10: 13.16 | H10: 12.47 | I10: 3,42/4,01 | J10: За запитом
C11: GUC-76Z-SA | D11: 8HP | E11: 22.4 | F11: 25 | G11: 5.21 | H11: 5.77 | I11: 4,3/4,33 | J11: За запитом | K11: Full DC inverter 380-415V/3PH/50HZ New Generation cooling under 52℃ heating under -25℃
C12: GUC-96Z-SA | D12: 10HP | E12: 28 | F12: 31.5 | G12: 7 | H12: 7.59 | I12: 4/4,15 | J12: За запитом
C13: GUC-114Z-SA | D13: 12HP | E13: 33.5 | F13: 37.5 | G13: 8.65 | H13: 9.21 | I13: 3,87/4,07 | J13: За запитом
C14: GUC-136Z-SA | D14: 14HP | E14: 40 | F14: 45 | G14: 10.53 | H14: 11.72 | I14: 3,8/3,84 | J14: За запитом
C15: GUC-154Z-SA | D15: 16HP | E15: 45 | F15: 50 | G15: 12.5 | H15: 13.7 | I15: 3,6/3,65 | J15: За запитом
C16: GUC-170Z-SA | D16: 18HP | E16: 50 | F16: 56 | G16: 15.63 | H16: 16.97 | I16: 3,2/3,3 | J16: За запитом
C17: GUC-190Z-SA | D17: 20HP | E17: 56 | F17: 63 | G17: 17.9 | H17: 19.87 | I17: 3,13/3,17 | J17: За запитом
C18: GUC-212Z-SA | D18: 22HP | E18: 61.5 | F18: 69 | G18: 20.5 | H18: 22.48 | I18: 3/3,07 | J18: За запитом
C19: GUC-232Z-SA | D19: 24HP | E19: 68 | F19: 75 | G19: 22.82 | H19: 24.59 | I19: 2,98/3,05 | J19: За запитом
C20: GUC-250Z-SA | D20: 26HP | E20: 72.5 | F20: 80 | G20: 24.58 | H20: 26.67 | I20: 2,95/3 | J20: За запитом
C21: GUC-272Z-SA | D21: 28HP | E21: 80 | F21: 90 | G21: 27.59 | H21: 30.41 | I21: 2,9/2,96 | J21: За запитом
C22: GUC-48Z-DSH2 | D22: 5HP | E22: 14 | F22: 16 | G22: 3.92 | H22: 4.03 | I22: 3,57/3,97 | J22: За запитом | K22: 380-415V/3PH/50HZ
C23: GUC-54Z-DSH2 | D23: 6HP | E23: 15.5 | F23: 18 | G23: 4.44 | H23: 4.74 | I23: 3,49/3,80 | J23: За запитом
C24: GUC-76Z-SH | D24: 8HP | E24: 22.4 | F24: 25 | G24: 6.36 | H24: 5.81 | I24: 3,52/4,30 | J24: За запитом
C25: GUC-96Z-SH | D25: 10HP | E25: 28 | F25: 31.5 | G25: 7.8 | H25: 7 | I25: 3,59/4,50 | J25: За запитом
C26: GUC-114Z-SH | D26: 12HP | E26: 33.5 | F26: 37.5 | G26: 10.6 | H26: 10.11 | I26: 3,16/3,71 | J26: За запитом
C27: GUC-38Z-DNH | D27: 4HP | E27: 11.2 | F27: 12.5 | G27: 2.6 | H27: 2.78 | I27: 4,31/4,50 | J27: За запитом | K27: 220-240V/1PH/50HZ
C28: GUC-48Z-DNH | D28: 5HP | E28: 14 | F28: 16 | G28: 3.46 | H28: 3.71 | I28: 4,05/4,31 | J28: За запитом
C29: GUC-54Z-DNH | D29: 6HP | E29: 15.5 | F29: 18 | G29: 4.21 | H29: 4.47 | I29: 3,68/4,03 | J29: За запитом
C30: GUC-28Z-NH | D30: 3HP | E30: 8 | F30: 9.5 | G30: 1.93 | H30: 2.37 | I30: 4,15/4,01 | J30: За запитом | K30: 220-240V/1PH/50HZ
C31: GUC-34Z-NH | D31: 4HP | E31: 10 | F31: 11.2 | G31: 2.34 | H31: 3.01 | I31: 4,27/3,72 | J31: За запитом
C32: GUC-43Z-NH | D32: 5HP | E32: 12.5 | F32: 14 | G32: 2.98 | H32: 4.15 | I32: 4,19/3,37 | J32: За запитом
C33: GUC-43Z-SH | D33: 5HP | E33: 12.5 | F33: 14 | G33: 3.81 | H33: 3.68 | I33: 3,28/3,8 | J33: За запитом | K33: 380-415V/3PH/50HZ
B38: Належність | C38: Найменування | D38: РРЦ, У.Е. | E38: Примітка
B39: AHU Kits | C39: GZX-2.0AEC | D39: За запитом | E39: 1Ф,220～240V/ 50/60Hz
C40: GZX-4.0AEC | D40: За запитом
C41: GZX-6.0AEC | D41: За запитом
C42: GZX-10.0AEC | D42: За запитом
C43: GZX-20.0AEC | D43: За запитом
C44: GZX-30.0AEC | D44: За запитом
B48: AHU Kits | C48: Номінальна потужність повітрообробної установки, НР | D48: Номінальна потужність повітрообробної установки, кВт.
B49: GZX-2.0AEC | C49: 2 | D49: 5.6
...

Sheet Galactic ТН
C4: Найменування | D4: Опис | E4: Роздрібна ціна, у.е., у.е.=$
B6: Комплект 4,4 кВт R32
C7: GHW-044HCDS1 | D7: Зовнішній блок, 4,4 кВт | E7: 2267.616
C8: GHM-044HCDSAA | D8: Гідромодуль | E8: 3867.864
C9: Разом | E9: =SUM(E7:E8) -> 6135.48
C10: Комплект 6 кВт R32
C11: GHW-060HCDS1 | D11: Зовнішній блок, 6 кВт | E11: 2364.492
C12: GHM-060HCDSAA | D12: Гідромодуль | E12: 4154.904
C13: Разом | E13: =SUM(E11:E12) -> 6519.396
C14: Комплект 8 кВт R32
C15: GHW-080HCDS1 | D15: Зовнішній блок, 8 кВт | E15: 2472.132
C16: GHM-080HCDSAA | D16: Гідромодуль | E16: 4621.344
C17: Разом | E17: =SUM(E15:E16) -> 7093.476
B18: Комплект 4,4 кВт з накопичувачем R32
C19: GHW-044HCDS2 | D19: Зовнішній блок, 4,4 кВт | E19: 2267.616
C20: GHS-044HCDSAA-23 | D20: Гідромодуль із баком 230л | E20: 6035.016
C21: Разом | E21: =SUM(E19:E20) -> 8302.632
C22: Комплект 6 кВт з накопичувачем R32
C23: GHW-060HCDS2 | D23: Зовнішній блок, 6 кВт | E23: 2364.492
C24: GHS-060HCDSAA-23 | D24: Гідромодуль із баком 230л | E24: 6307.704
C25: Разом | E25: =SUM(E23:E24) -> 8672.196
C26: Комплект 8 кВт з накопичувачем R32
C27: GHW-080HCDS2 | D27: Зовнішній блок, 8 кВт | E27: 2472.132
C28: GHS-080HCDSAA-23 | D28: Гідромодуль із баком 230л | E28: 6673.68
C29: Разом | E29: =SUM(E27:E28) -> 9145.812
B30: Моноблочні теплові насоси
C31: GHZ-044HCDS1 | D31: Т.Н. 4,4 кВт | E31: 5697.744
C32: GHZ-080HCDS1 | D32: Т.Н. 8 кВт | E32: 5984.784
B33: АКСЕСУАРИ
B34: HTS-E1000A | C34: Датчик температури води | E34: 39.468
B35: HC-T-01M | C35: Датчик температури навколишнього середовища | E35: 46.644
B36: HSXE-VC04 | C36: Кімнатний контролер | E36: 125.58

Sheet REMAK
B6: Найменування обладнання | D6: Коментар | E6: Роздрібна ціна, € | F6: 0
B7: Канальні радіальні вентилятори з EC моторами RE – однофазні
B8: RE 30-15/19-SE | E8: За запитом | F8: =E8*(100%-$F$6) -> #VALUE!
B9: RE 40-20/22-SE | E9: За запитом | F9: =E9*(100%-$F$6) -> #VALUE!
B10: RE 50-25/28-SE | E10: За запитом | F10: =E10*(100%-$F$6) -> #VALUE!
B11: RE 50-30/28-SE | E11: За запитом | F11: =E11*(100%-$F$6) -> #VALUE!
B12: RE 60-30/31-SE | E12: За запитом | F12: =E12*(100%-$F$6) -> #VALUE!
B13: RE 60-35/35-SE | E13: За запитом | F13: =E13*(100%-$F$6) -> #VALUE!
B14: RE 70-40/40-SE | E14: За запитом | F14: =E14*(100%-$F$6) -> #VALUE!
B15: Канальні радіальні вентилятори з EC моторами RE – трифазні
B16: RE 60-35/35-SD | E16: За запитом | F16: =E16*(100%-$F$6) -> #VALUE!
B17: RE 70-40/40-SD | E17: За запитом | F17: =E17*(100%-$F$6) -> #VALUE!
B18: RE 80-50/50-LD | E18: За запитом | F18: =E18*(100%-$F$6) -> #VALUE!
B19: RE 80-50/50-SD | E19: За запитом | F19: =E19*(100%-$F$6) -> #VALUE!
B20: RE 90-50/45-SD | E20: За запитом | F20: =E20*(100%-$F$6) -> #VALUE!
B21: RE 90-50/50-SD | E21: За запитом | F21: =E21*(100%-$F$6) -> #VALUE!
B22: RE 100-50/45-SD | E22: За запитом | F22: =E22*(100%-$F$6) -> #VALUE!
B23: RE 100-50/50-SD | E23: За запитом | F23: =E23*(100%-$F$6) -> #VALUE!
B24: RE 100-50/56-SD | E24: За запитом | F24: =E24*(100%-$F$6) -> #VALUE!
B25: Канальні радіальні вентилятори RO – однофазні
B26: RO 30-15/19-2E | E26: За запитом | F26: =E26*(100%-$F$6) -> #VALUE!
B27: RO 40-20/22-2E | E27: За запитом | F27: =E27*(100%-$F$6) -> #VALUE!
B28: RO 50-25/25-2E | E28: За запитом | F28: =E28*(100%-$F$6) -> #VALUE!
B29: Канальні радіальні вентилятори RO – трифазні
B30: RO 50-30/31-4D | E30: За запитом | F30: =E30*(100%-$F$6) -> #VALUE!
B31: RO 60-35/35-4D | E31: За запитом | F31: =E31*(100%-$F$6) -> #VALUE!
B32: RO 70-40/40-4D | E32: За запитом | F32: =E32*(100%-$F$6) -> #VALUE!
B33: RO 80-50/45-4D | E33: За запитом | F33: =E33*(100%-$F$6) -> #VALUE!
B34: RO 80-50/50-4D | E34: За запитом | F34: =E34*(100%-$F$6) -> #VALUE!
B35: RO 90-50/50-4D | E35: За запитом | F35: =E35*(100%-$F$6) -> #VALUE!
B36: RO 100-50/56-4D | E36: За запитом | F36: =E36*(100%-$F$6) -> #VALUE!
B37: Канальні радіальні вентилятори RP – однофазні
B38: RP 40-20/20-4E | E38: За запитом | F38: =E38*(100%-$F$6) -> #VALUE!
B39: RP 50-25/22-4E | E39: За запитом | F39: =E39*(100%-$F$6) -> #VALUE!
B40: RP 50-30/25-4E | E40: За запитом | F40: =E40*(100%-$F$6) -> #VALUE!
B41: RP 60-30/28-4E | E41: За запитом | F41: =E41*(100%-$F$6) -> #VALUE!
B42: Канальні радіальні вентилятори RP – трифазні
B43: RP 40-20/20-4D | E43: За запитом | F43: =E43*(100%-$F$6) -> #VALUE!
B44: RP 50-25/22-4D | E44: За запитом | F44: =E44*(100%-$F$6) -> #VALUE!
B45: RP 50-25/22-6D | E45: За запитом | F45: =E45*(100%-$F$6) -> #VALUE!
...

Sheet REMAK ЗАВІСИ
B19: Тип завіси | C19: Модель | E19: Роздрібна ціна, € | F19: 0
B20: Без обігріву | C20: C1-N-100 | E20: 1119 | F20: =E20*(100%-$F$19) -> 1119
C21: C1-N-100/TR | E21: 1199 | F21: =E21*(100%-$F$19) -> 1199
C22: C1-N-150 | E22: 1611 | F22: =E22*(100%-$F$19) -> 1611
C23: C1-N-150/TR | E23: 1693 | F23: =E23*(100%-$F$19) -> 1693
C24: C1-N-200 | E24: 1907 | F24: =E24*(100%-$F$19) -> 1907
C25: C1-N-200/TR | E25: 1990 | F25: =E25*(100%-$F$19) -> 1990
B26: З електрообігрівом | C26: C1-E1-100 | E26: 1614 | F26: =E26*(100%-$F$19) -> 1614
C27: C1-E1-100/M | E27: 1630 | F27: =E27*(100%-$F$19) -> 1630
C28: C1-E1-100/TR | E28: 1662 | F28: =E28*(100%-$F$19) -> 1662
C29: C1-E1-100/TR-M | E29: 1682 | F29: =E29*(100%-$F$19) -> 1682
C30: C1-E1-150 | E30: 2129 | F30: =E30*(100%-$F$19) -> 2129
C31: C1-E1-150/M | E31: 2150 | F31: =E31*(100%-$F$19) -> 2150
C32: C1-E1-150/TR | E32: 2220 | F32: =E32*(100%-$F$19) -> 2220
C33: C1-E1-150/TR-M | E33: 2242 | F33: =E33*(100%-$F$19) -> 2242
C34: C1-E1-200 | E34: 2554 | F34: =E34*(100%-$F$19) -> 2554
C35: C1-E1-200/M | E35: 2574 | F35: =E35*(100%-$F$19) -> 2574
C36: C1-E1-200/TR | E36: 2609 | F36: =E36*(100%-$F$19) -> 2609
C37: C1-E1-200/TR-M | E37: 2630 | F37: =E37*(100%-$F$19) -> 2630
C38: C1-E2-100 | E38: 1737 | F38: =E38*(100%-$F$19) -> 1737
... C49: C1-E2-200/TR-M | E49: 2862 | F49: =E49*(100%-$F$19) -> 2862
B50: З водяним обігрівом | C50: C1-W-100 | E50: 1359 | F50: =E50*(100%-$F$19) -> 1359
C51: C1-W-100/TR | E51: 1440 | F51: =E51*(100%-$F$19) -> 1440
C52: C1-W-150 | E52: 1923 | F52: =E52*(100%-$F$19) -> 1923
C53: C1-W-150/TR | E53: 1999 | F53: =E53*(100%-$F$19) -> 1999
C54: C1-W-200 | E54: 2214 | F54: =E54*(100%-$F$19) -> 2214
C55: C1-W-200/TR | E55: 2294 | F55: =E55*(100%-$F$19) -> 2294
B70: Тип завіси | C70: Модель | E70: Роздрібна ціна, € | F70: =F19 -> 0
B71: Без обігріву | C71: D2-N-100/S2 | E71: 2254 | F71: =E71*(100%-$F$19) -> 2254
C72: D2-N-100/S2-M | E72: 2274 | F72: =E72*(100%-$F$19) -> 2274
C73: D2-N-150 | E73: 3028 | F73: =E73*(100%-$F$19) -> 3028
C74: D2-N-150/S2 | E74: 3028 | F74: =E74*(100%-$F$19) -> 3028
C75: D2-N-150/S2-M | E75: 3050 | F75: =E75*(100%-$F$19) -> 3050
C76: D2-N-200/S2 | E76: 3972 | F76: =E76*(100%-$F$19) -> 3972
C77: D2-N-200/S2-M | E77: 3994 | F77: =E77*(100%-$F$19) -> 3994
C78: D2-N-250/S2 | E78: 4623 | F78: =E78*(100%-$F$19) -> 4623
C79: D2-N-250/S2-M | E79: 4645 | F79: =E79*(100%-$F$19) -> 4645
B80: З електрообігрівом | C80: D2-E1-100/S2 | E80: 2878 | F80: =E80*(100%-$F$19) -> 2878
C81: D2-E1-100/S2-M | E81: 2898 | F81: =E81*(100%-$F$19) -> 2898
C82: D2-E2-100/S2 | E82: 2975 | F82: =E82*(100%-$F$19) -> 2975
...

Sheet VRF Зовнішні блоки
B5: Зовнішні блоки
B6: Модель | C6: Тип блоку | D6: Фазність | E6: ПОТУЖНІСТЬ | G6: Роздрібна ціна, у.е., у.е.=дол.
B7: Micro KXZ (1-Fan) R410A
C8: FDC121KXZEN1 | D8: 1 фаза | E8: 12100 | F8: 12100 | G8: 4014.3432
C9: FDC121KXZES1 | D9: 3 фази | E9: 12100 | F9: 12100 | G9: 4014.3432
C10: FDC140KXZEN1 | D10: 1 фаза | E10: 14000 | F10: 14000 | G10: 4502.0927
C11: FDC140KXZES1 | D11: 3 фази | E11: 14000 | F11: 14000 | G11: 4502.0927
C12: FDC155KXZEN1 | D12: 1 фаза | E12: 15500 | F12: 15500 | G12: 4984.362
C13: FDC155KXZES1 | D13: 3 фази | E13: 15500 | F13: 15500 | G13: 4984.362
C14: http://mitsubishiheavy.com.ua/catalog/micro-kx/
B15: Micro KXZ (1-Fan) R32
C16: FDC121KXZEN1-W | D16: 1 фаза | E16: 12100 | F16: 12100 | G16: 4093.808
C17: FDC121KXZES1-W | D17: 3 фази | E17: 12100 | F17: 12100 | G17: 4093.808
C18: FDC140KXZEN1-W | D18: 1 фаза | E18: 14000 | F18: 14000 | G18: 4592.5182
C19: FDC140KXZES1-W | D19: 3 фази | E19: 14000 | F19: 14000 | G19: 4592.5182
C20: FDC155KXZEN1-W | D20: 1 фаза | E20: 15500 | F20: 15500 | G20: 5085.7481
C21: FDC155KXZES1-W | D21: 3 фази | E21: 15500 | F21: 15500 | G21: 5085.7481
C22: http://mitsubishiheavy.com.ua/catalog/micro-kx/
B24: Micro KXZ (2-Fans) R410A
C25: FDC224KXZME1 | E25: 22400 | F25: 22400 | G25: 7877.9773
C26: FDC280KXZME1 | E26: 28000 | F26: 28000 | G26: 8886.3583
C27: FDC335KXZME1A | E27: 33500 | F27: 33500 | G27: 10582.521
C28: http://mitsubishiheavy.com.ua/catalog/micro-kx/
B29: KXZ Lite R410A
C30: FDC224KXZPE1 | E30: 22400 | F30: 22400 | G30: 6085.9087
C31: FDC280KXZPE1 | E31: 28000 | F31: 28000 | G31: 6861.3757
C32: http://mitsubishiheavy.com.ua/catalog/kxzp/
B33: KXZ-покращений COP, низький рівень шуму R410A
C34: FDC280KXZE2 | D34: 3 фази | E34: 28000 | F34: 31500 | G34: 9557.699
C35: FDC335KXZE2 | D35: 3 фази | E35: 33500 | F35: 37500 | G35: 11114.113
C36: FDC400KXZE2 | D36: 3 фази | E36: 40000 | F36: 45000 | G36: 13196.639
C37: FDC450KXZE2 | D37: 3 фази | E37: 45000 | F37: 50000 | G37: 14679.069
C38: FDC475KXZE2 | D38: 3 фази | E38: 47500 | F38: 53000 | G38: 15443.576
C39: FDC500KXZE2 | D39: 3 фази | E39: 50000 | F39: 56000 | G39: 16797.218
C40: FDC560KXZE2 | D40: 3 фази | E40: 56000 | F40: 63000 | G40: 17980.969
C41: FDC560KXZE2 | D41: 280KXZE2 + 280KXZE2+DOS-2A-3 | E41: 56000 | F41: 63000
C42: FDC615KXZE2 | D42: 280KXZE2 + 335KXZE2+DOS-2A-3 | E42: 61500 | F42: 69000
C43: FDC670KXZE2 | D43: 335KXZE2 + 335KXZE2+DOS-2A-3 | E43: 67000 | F43: 75000
C44: FDC735KXZE2 | D44: 400KXZE2 + 335KXZE2+DOS-2A-3 | E44: 73500 | F44: 82500
C45: FDC800KXZE2 | D45: 400KXZE2 + 400KXZE2+DOS-2A-3 | E45: 80000 | F45: 90000
...

Sheet VRF Внутрішні R410A
B5: Внутрішні блоки
B6: НАЙМЕНУВАННЯ БЛОКУ | E6: ПОТУЖНІСТЬ | G6: Роздрібна ціна MHI
E7: Охолодження, Вт | F7: Нагрів, Вт
B8: ВНУТРІШНІ БЛОКИ
B9: FDE | C9: Стельово-підвісного типу
C10: FDE36KXZE1 | D10: Вартість пульта в аксесуарах | E10: 3600 | F10: 4000 | G10: 1635.8791
C11: FDE45KXZE1 | E11: 4500 | F11: 5000 | G11: 1704.3833
C12: FDE56KXZE1 | E12: 5600 | F12: 6300 | G12: 1775.6276
C13: FDE71KXZE1 | E13: 7100 | F13: 8000 | G13: 1852.3522
C14: FDE112KXZE1 | E14: 11200 | F14: 12500 | G14: 2104.4475
C15: FDE140KXZE1 | E15: 14000 | F15: 16000 | G15: 2504.5117
B16: FDK-Z | C16: Настінного типу дизайнерська серія
C17: FDK15KXZE1 | D17: Вартість пульта в аксесуарах | E17: 1500 | F17: 1700 | G17: 734.36449
C18: FDK22KXZE1 | E18: 2200 | F18: 2500 | G18: 737.10465
C19: FDK28KXZE1 | E19: 2800 | F19: 3200 | G19: 756.28582
C20: FDK36KXZE1 | E20: 3600 | F20: 4000 | G20: 780.94731
C21: FDK45KXZE1 | E21: 4500 | F21: 5000 | G21: 805.6088
C22: FDK56KXZE1 | E22: 5600 | F22: 6300 | G22: 874.11295
C23: FDK71KXZE1 | E23: 7100 | F23: 8000 | G23: 939.87694
C24: FDK90KXZE1 | E24: 9000 | F24: 10000 | G24: 1107.0271
B25: FDTC | C25: Касетного типу - компактні (600 мм)
C26: FDTC15KXZE1 | D26: Вартість панелі та пульта в аксесуарах | E26: 1500 | F26: 1650 | G26: 1016.6016
C27: FDTC22KXZE1 | E27: 2200 | F27: 2500 | G27: 1142.6492
C28: FDTC28KXZE1 | E28: 2800 | F28: 3200 | G28: 1186.4919
C29: FDTC36KXZE1 | E29: 3600 | F29: 4000 | G29: 1205.673
C30: FDTC45KXZE1 | E30: 4500 | F30: 5000 | G30: 1290.6182
C31: FDTC56KXZE1 | E31: 5600 | F31: 6300 | G31: 1323.5002
B32: FDT-Z | C32: 4-потокові касетного типу
C33: FDT28KXZE1 | D33: Вартість панелі та пульта в аксесуарах | E33: 2800 | F33: 3200 | G33: 1079.6254
C34: FDT36KXZE1 | E34: 3600 | F34: 4000 | G34: 1131.6886
C35: FDT45KXZE1 | E35: 4500 | F35: 5000 | G35: 1200.1927
C36: FDT56KXZE1 | E36: 5600 | F36: 6300 | G36: 1274.1772
C37: FDT71KXZE1 | E37: 7100 | F37: 8000 | G37: 1328.9805
C38: FDT90KXZE1 | E38: 9000 | F38: 10000 | G38: 1652.3201
C39: FDT112KXZE1 | E39: 11200 | F39: 12500 | G39: 1844.1317
C40: FDT140KXZE1 | E40: 14000 | F40: 16000 | G40: 2041.4237
C41: FDT160KXZE1 | E41: 16000 | F41: 18500 | G41: 2403.1256
B42: FDTQ | C42: 1-потоковий касетного типу
C43: FDTQ22KXE6F | D43: Вартість панелі та пульта в аксесуарах | E43: 2200 | F43: 2500 | G43: 1276.9174
C44: FDTQ28KXE6F | E44: 2800 | F44: 3200 | G44: 1298.8387
...

Sheet VRF Внутрішні KXZE1-W R32
B4: Внутрішні блоки
B5: НАЙМЕНУВАННЯ БЛОКУ | E5: ПОТУЖНІСТЬ | G5: Роздрібна ціна MHI
E6: Охолодження, Вт | F6: Нагрів, Вт
B7: ВНУТРІШНІ БЛОКИ
B8: FDK | C8: Настінного типу дизайнерська серія не сумістний з KXZE3
C9: FDK15KXZE1-W | D9: Вартість пульта в аксесуарах | E9: 1500 | F9: 1700 | G9: 745.32515
C10: FDK22KXZE1-W | E10: 2200 | F10: 2500 | G10: 753.54565
C11: FDK28KXZE1-W | E11: 2800 | F11: 3200 | G11: 769.98665
C12: FDK36KXZE1-W | E12: 3600 | F12: 4000 | G12: 794.64814
